Workbook
Name rng: 'data'!$A$1:$B$5
Name local_rng: 'calc'!$A$1:$B$5
Name hidden_rng: 'calc'!$A$1:$A$3
Name const_num: 3.14159
Name const_str: "text"
Name const_arr: {1,2,3;4,5,6}
Name fml_name: SUM(data!$B$2:$B$21)*2
Name ofs: OFFSET(data!$A$1,0,0,COUNTA(data!$A:$A),1)
Name cmt: data!$D$2
Name multi: (data!$A$1,data!$B$1:$B$3)
Name three_d: data:calc!$A$1

Sheet data
B1: mpg | C1: cyl | D1: disp | E1: hp | F1: drat | G1: wt | H1: qsec | I1: vs | J1: am | K1: gear | L1: carb
A2: Mazda RX4 | B2: 21 | C2: 6 | D2: 160 | E2: 110 | F2: 3.9 | G2: 2.62 | H2: 16.46 | I2: 0 | J2: 1 | K2: 4 | L2: 4
A3: Mazda RX4 Wag | B3: 21 | C3: 6 | D3: 160 | E3: 110 | F3: 3.9 | G3: 2.875 | H3: 17.02 | I3: 0 | J3: 1 | K3: 4 | L3: 4
A4: Datsun 710 | B4: 22.8 | C4: 4 | D4: 108 | E4: 93 | F4: 3.85 | G4: 2.32 | H4: 18.61 | I4: 1 | J4: 1 | K4: 4 | L4: 1
A5: Hornet 4 Drive | B5: 21.4 | C5: 6 | D5: 258 | E5: 110 | F5: 3.08 | G5: 3.215 | H5: 19.44 | I5: 1 | J5: 0 | K5: 3 | L5: 1
A6: Hornet Sportabout | B6: 18.7 | C6: 8 | D6: 360 | E6: 175 | F6: 3.15 | G6: 3.44 | H6: 17.02 | I6: 0 | J6: 0 | K6: 3 | L6: 2
A7: Valiant | B7: 18.1 | C7: 6 | D7: 225 | E7: 105 | F7: 2.76 | G7: 3.46 | H7: 20.22 | I7: 1 | J7: 0 | K7: 3 | L7: 1
A8: Duster 360 | B8: 14.3 | C8: 8 | D8: 360 | E8: 245 | F8: 3.21 | G8: 3.57 | H8: 15.84 | I8: 0 | J8: 0 | K8: 3 | L8: 4
A9: Merc 240D | B9: 24.4 | C9: 4 | D9: 146.7 | E9: 62 | F9: 3.69 | G9: 3.19 | H9: 20 | I9: 1 | J9: 0 | K9: 4 | L9: 2
A10: Merc 230 | B10: 22.8 | C10: 4 | D10: 140.8 | E10: 95 | F10: 3.92 | G10: 3.15 | H10: 22.9 | I10: 1 | J10: 0 | K10: 4 | L10: 2
A11: Merc 280 | B11: 19.2 | C11: 6 | D11: 167.6 | E11: 123 | F11: 3.92 | G11: 3.44 | H11: 18.3 | I11: 1 | J11: 0 | K11: 4 | L11: 4
A12: Merc 280C | B12: 17.8 | C12: 6 | D12: 167.6 | E12: 123 | F12: 3.92 | G12: 3.44 | H12: 18.9 | I12: 1 | J12: 0 | K12: 4 | L12: 4
A13: Merc 450SE | B13: 16.4 | C13: 8 | D13: 275.8 | E13: 180 | F13: 3.07 | G13: 4.07 | H13: 17.4 | I13: 0 | J13: 0 | K13: 3 | L13: 3
... A21: Toyota Corolla | B21: 33.9 | C21: 4 | D21: 71.1 | E21: 65 | F21: 4.22 | G21: 1.835 | H21: 19.9 | I21: 1 | J21: 1 | K21: 4 | L21: 1

Sheet calc
A1: f | C1: =SUM(data!B2:B21) | E1: {=A1:A3*2} | F1: {=SUM(A1:A10*A1:A10)}
A2: 1 | C2: =AVERAGE(rng)
A3: 2 | C3: =IF(A1>5,"hi","lo")
A4: 3 | C4: =VLOOKUP("Mazda RX4",data!A1:L21,2,FALSE)
A5: 4 | C5: =INDEX(data!B2:D21,MATCH("Valiant",data!A2:A21,0),2)
A6: 5 | C6: =SUMPRODUCT((data!B2:B21>6)*(data!C2:C21))
A7: 6 | C7: =TEXT(A1,"0.00")&"x"
A8: 7 | C8: =CONCATENATE("a","b")
A9: 8 | C9: =LEFT("abcdef",3)&MID("abcdef",2,2)&RIGHT("abcdef",1)
A10: 9 | C10: =ROUND(PI(),3)
A11: 10 | C11: =DATE(2020,1,31)+EDATE(DATE(2020,1,31),1)
A12: 11 | C12: =NETWORKDAYS(DATE(2020,1,1),DATE(2020,2,1))
A13: 12 | C13: =IFERROR(1/0,"err")
A14: 13 | C14: =ISNUMBER(A1)
A15: 14 | C15: =AND(TRUE,FALSE)
A16: 15 | C16: =OR(TRUE,FALSE)
A17: 16 | C17: =NOT(TRUE)
A18: 17 | C18: =CHOOSE(2,"a","b","c")
A19: 18 | C19: =COUNTIF(A1:A10,">5")
A20: 19 | C20: =SUMIF(A1:A10,">5",A1:A10)
A21: 20 | C21: =SUMIFS(A1:A10,A1:A10,">2",A1:A10,"<8")
A22: 21 | C22: =COUNTIFS(A1:A10,">2",A1:A10,"<8")
A23: 22 | C23: =MAX(A1:A10)-MIN(A1:A10)
A24: 23 | C24: =LARGE(A1:A10,2)
A25: 24 | C25: =RANK(A2,A1:A10)
A26: 25 | C26: =STDEV(A1:A10)
A27: 26 | C27: =MEDIAN(A1:A10)
A28: 27 | C28: =MOD(A1,3)
A29: 28 | C29: =POWER(2,10)
A30: 29 | C30: =SQRT(16)
A31: 30 | C31: =ABS(-3)
A32: 31 | C32: =INT(2.7)
A33: 32 | C33: =LN(EXP(1))
A34: 33 | C34: =FIND("b","abc")
A35: 34 | C35: =SUBSTITUTE("aaa","a","b")
A36: 35 | C36: =LEN("abc")
A37: 36 | C37: =TRIM(" a ")
A38: 37 | C38: =UPPER("a")&LOWER("B")&PROPER("cd")
A39: 38 | C39: =ROW()+COLUMN()
A40: 39 | C40: =ROWS(A1:A10)+COLUMNS(A1:C1)
...
